Traceback (most recent call last):
  File "/opt/hostedtoolcache/Python/3.8.6/x64/lib/python3.8/site-packages/jupyter_cache/executors/utils.py", line 51, in single_nb_execution
    executenb(
  File "/opt/hostedtoolcache/Python/3.8.6/x64/lib/python3.8/site-packages/nbclient/client.py", line 1087, in execute
    return NotebookClient(nb=nb, resources=resources, km=km, **kwargs).execute()
  File "/opt/hostedtoolcache/Python/3.8.6/x64/lib/python3.8/site-packages/nbclient/util.py", line 74, in wrapped
    return just_run(coro(*args, **kwargs))
  File "/opt/hostedtoolcache/Python/3.8.6/x64/lib/python3.8/site-packages/nbclient/util.py", line 53, in just_run
    return loop.run_until_complete(coro)
  File "/opt/hostedtoolcache/Python/3.8.6/x64/lib/python3.8/asyncio/base_events.py", line 616, in run_until_complete
    return future.result()
  File "/opt/hostedtoolcache/Python/3.8.6/x64/lib/python3.8/site-packages/nbclient/client.py", line 540, in async_execute
    await self.async_execute_cell(
  File "/opt/hostedtoolcache/Python/3.8.6/x64/lib/python3.8/site-packages/nbclient/client.py", line 832, in async_execute_cell
    self._check_raise_for_error(cell, exec_reply)
  File "/opt/hostedtoolcache/Python/3.8.6/x64/lib/python3.8/site-packages/nbclient/client.py", line 740, in _check_raise_for_error
    raise CellExecutionError.from_cell_and_msg(cell, exec_reply['content'])
nbclient.exceptions.CellExecutionError: An error occurred while executing the following cell:
------------------
df_crime = pd.read_csv(filepath_or_buffer=FOLDER_RAW + "/" + DATA_CRIME,
                       parse_dates=["Outcome Date", "Epoch"])
df_pop = pd.read_excel(io=FOLDER_RAW + "/" + DATA_POP,
                       sheet_name="WardP Summry",
                       header=None,
                       names=['Ward Code',
                              'Ward Name',
                              '2015',
                              '2016',
                              '2017',
                              '2018',
                              '2019',
                              '2020'],
                       usecols="B,D,K:P",
                       skiprows=5,
                       nrows=18)
shp_ward = gpd.read_file(filename=FOLDER_RAW + "/camden_ward_boundary/" + DATA_MAP)
shp_light = gpd.read_file(filename=FOLDER_RAW + "/camden_street_lighting/" + DATA_LIGHT)
------------------

[0;31m---------------------------------------------------------------------------[0m
[0;31mTypeError[0m                                 Traceback (most recent call last)
[0;32m<ipython-input-2-944bf16676c8>[0m in [0;36m<module>[0;34m[0m
[0;32m----> 1[0;31m df_crime = pd.read_csv(filepath_or_buffer=FOLDER_RAW + "/" + DATA_CRIME,
[0m[1;32m      2[0m                        parse_dates=["Outcome Date", "Epoch"])
[1;32m      3[0m df_pop = pd.read_excel(io=FOLDER_RAW + "/" + DATA_POP,
[1;32m      4[0m                        [0msheet_name[0m[0;34m=[0m[0;34m"WardP Summry"[0m[0;34m,[0m[0;34m[0m[0;34m[0m[0m
[1;32m      5[0m                        [0mheader[0m[0;34m=[0m[0;32mNone[0m[0;34m,[0m[0;34m[0m[0;34m[0m[0m

[0;31mTypeError[0m: unsupported operand type(s) for +: 'NoneType' and 'str'
TypeError: unsupported operand type(s) for +: 'NoneType' and 'str'

